<sdf version='1.6'>
  <model name='A-2084-01'>
    <link name='HEBI/Base/INPUT_INTERFACE'>
      <pose frame=''>0 0 0 0 -0 0</pose>
      <inertial>
        <pose frame=''>-0.0142 -0.0031 0.0165 0 -0 0</pose>
        <mass>0.335</mass>
        <inertia>
          <ixx>0.00015</ixx>
          <ixy>3.41e-05</ixy>
          <ixz>1.18e-05</ixz>
          <iyy>0.000255</iyy>
          <iyz>2.29e-06</iyz>
          <izz>0.00035</izz>
        </inertia>
      </inertial>
      <collision name='HEBI/Base/INPUT_INTERFACE_collision'>
        <pose frame=''>0 0 0 0 -0 0</pose>
        <geometry>
          <mesh>
            <scale>0.001 0.001 0.001</scale>
            <uri>model://hebi_description/meshes/X5.stl</uri>
          </mesh>
        </geometry>
      </collision>
      <visual name='HEBI/Base/INPUT_INTERFACE_visual'>
        <pose frame=''>0 0 0 0 -0 0</pose>
        <geometry>
          <mesh>
            <scale>0.001 0.001 0.001</scale>
            <uri>model://hebi_description/meshes/X5.stl</uri>
          </mesh>
        </geometry>
      </visual>
    </link>
    <joint name='world_joint' type='fixed'>
      <child>HEBI/Base/INPUT_INTERFACE</child>
      <parent>world</parent>
    </joint>
    <link name='Shoulder_bracket/INPUT_INTERFACE'>
      <pose frame=''>0 0 0.031 0 -0 0</pose>
      <inertial>
        <pose frame=''>0 -0.01875 0.0275 0 -0 0</pose>
        <mass>0.215</mass>
        <inertia>
          <ixx>0.0003096</ixx>
          <ixy>0</ixy>
          <ixz>0</ixz>
          <iyy>0.0003096</iyy>
          <iyz>0</iyz>
          <izz>0.0003096</izz>
        </inertia>
      </inertial>
      <collision name='Shoulder_bracket/INPUT_INTERFACE_collision'>
        <pose frame=''>0 0 0.005 1.5708 -0 1.5708</pose>
        <geometry>
          <mesh>
            <scale>0.001 0.001 0.001</scale>
            <uri>model://hebi_description/meshes/PM-2149-01.stl</uri>
          </mesh>
        </geometry>
      </collision>
      <collision name='Shoulder_bracket/INPUT_INTERFACE_collision_1'>
        <pose frame=''>0 -0.03 0.04 1.5708 -0 0</pose>
        <geometry>
          <mesh>
            <scale>0.001 0.001 0.001</scale>
            <uri>model://hebi_description/meshes/PM-2150-01R.stl</uri>
          </mesh>
        </geometry>
      </collision>
      <visual name='Shoulder_bracket/INPUT_INTERFACE_visual'>
        <pose frame=''>0 0 0.005 1.5708 -0 1.5708</pose>
        <geometry>
          <mesh>
            <scale>0.001 0.001 0.001</scale>
            <uri>model://hebi_description/meshes/PM-2149-01.stl</uri>
          </mesh>
        </geometry>
      </visual>
      <visual name='Shoulder_bracket/INPUT_INTERFACE_visual_1'>
        <pose frame=''>0 -0.03 0.04 1.5708 -0 0</pose>
        <geometry>
          <mesh>
            <scale>0.001 0.001 0.001</scale>
            <uri>model://hebi_description/meshes/PM-2150-01R.stl</uri>
          </mesh>
        </geometry>
      </visual>
    </link>
    <joint name='HEBI/Base/X5_4' type='revolute'>
      <child>Shoulder_bracket/INPUT_INTERFACE</child>
      <parent>HEBI/Base/INPUT_INTERFACE</parent>
      <axis>
        <xyz>0 0 1</xyz>
        <limit>
          <lower>-1e+16</lower>
          <upper>1e+16</upper>
        </limit>
        <dynamics>
          <damping>0.1</damping>
          <friction>0.1</friction>
          <spring_reference>0</spring_reference>
          <spring_stiffness>0</spring_stiffness>
        </dynamics>
        <use_parent_model_frame>1</use_parent_model_frame>
      </axis>
    </joint>
    <link name='HEBI/Shoulder/INPUT_INTERFACE'>
      <pose frame=''>0 -0.0375 0.086 1.5708 -0 0</pose>
      <inertial>
        <pose frame=''>-0.0142 -0.0031 0.0165 0 -0 0</pose>
        <mass>0.36</mass>
        <inertia>
          <ixx>0.00015</ixx>
          <ixy>3.41e-05</ixy>
          <ixz>1.18e-05</ixz>
          <iyy>0.000255</iyy>
          <iyz>2.29e-06</iyz>
          <izz>0.00035</izz>
        </inertia>
      </inertial>
      <collision name='HEBI/Shoulder/INPUT_INTERFACE_collision'>
        <pose frame=''>0 0 0 0 -0 0</pose>
        <geometry>
          <mesh>
            <scale>0.001 0.001 0.001</scale>
            <uri>model://hebi_description/meshes/X5.stl</uri>
          </mesh>
        </geometry>
      </collision>
      <visual name='HEBI/Shoulder/INPUT_INTERFACE_visual'>
        <pose frame=''>0 0 0 0 -0 0</pose>
        <geometry>
          <mesh>
            <scale>0.001 0.001 0.001</scale>
            <uri>model://hebi_description/meshes/X5.stl</uri>
          </mesh>
        </geometry>
      </visual>
    </link>
    <joint name='Shoulder_bracket/OUTPUT_INTERFACE' type='fixed'>
      <child>HEBI/Shoulder/INPUT_INTERFACE</child>
      <parent>Shoulder_bracket/INPUT_INTERFACE</parent>
      <axis>
        <dynamics>
          <spring_reference>0</spring_reference>
          <spring_stiffness>0</spring_stiffness>
        </dynamics>
        <use_parent_model_frame>1</use_parent_model_frame>
        <xyz>0 0 1</xyz>
        <limit>
          <lower>-1e+16</lower>
          <upper>1e+16</upper>
        </limit>
      </axis>
      <physics>
        <ode>
          <limit>
            <cfm>0</cfm>
            <erp>0.2</erp>
          </limit>
        </ode>
      </physics>
    </joint>
    <link name='Shoulder_Elbow/INPUT_INTERFACE'>
      <pose frame=''>0 -0.0685 0.086 1.5708 -0 0</pose>
      <inertial>
        <pose frame=''>0.1625 0 0.02 0 -0 0</pose>
        <mass>0.402</mass>
        <inertia>
          <ixx>0</ixx>
          <ixy>0</ixy>
          <ixz>0</ixz>
          <iyy>0.00353844</iyy>
          <iyz>0</iyz>
          <izz>0.00353844</izz>
        </inertia>
      </inertial>
      <collision name='Shoulder_Elbow/INPUT_INTERFACE_collision'>
        <pose frame=''>0 0 0 0 -0 0</pose>
        <geometry>
          <mesh>
            <scale>1 1 1</scale>
            <uri>model://hebi_description/meshes/A-2038-02.stl</uri>
          </mesh>
        </geometry>
      </collision>
      <collision name='Shoulder_Elbow/INPUT_INTERFACE_collision_1'>
        <pose frame=''>0.1625 0 0.02 3.14159 1.57079 3.14159</pose>
        <geometry>
          <cylinder>
            <length>0.2996</length>
            <radius>0.016</radius>
          </cylinder>
        </geometry>
      </collision>
      <collision name='Shoulder_Elbow/INPUT_INTERFACE_collision_2'>
        <pose frame=''>0.325 -0.02 0.02 -1.5708 0 0</pose>
        <geometry>
          <mesh>
            <scale>1 1 1</scale>
            <uri>model://hebi_description/meshes/A-2039-02.stl</uri>
          </mesh>
        </geometry>
      </collision>
      <visual name='Shoulder_Elbow/INPUT_INTERFACE_visual'>
        <pose frame=''>0 0 0 0 -0 0</pose>
        <geometry>
          <mesh>
            <scale>1 1 1</scale>
            <uri>model://hebi_description/meshes/A-2038-02.stl</uri>
          </mesh>
        </geometry>
      </visual>
      <visual name='Shoulder_Elbow/INPUT_INTERFACE_visual_1'>
        <pose frame=''>0.1625 0 0.02 3.14159 1.57079 3.14159</pose>
        <geometry>
          <cylinder>
            <length>0.2996</length>
            <radius>0.016</radius>
          </cylinder>
        </geometry>
      </visual>
      <visual name='Shoulder_Elbow/INPUT_INTERFACE_visual_2'>
        <pose frame=''>0.325 -0.02 0.02 -1.5708 0 0</pose>
        <geometry>
          <mesh>
            <scale>1 1 1</scale>
            <uri>model://hebi_description/meshes/A-2039-02.stl</uri>
          </mesh>
        </geometry>
      </visual>
    </link>
    <joint name='HEBI/Shoulder/X5_9' type='revolute'>
      <child>Shoulder_Elbow/INPUT_INTERFACE</child>
      <parent>HEBI/Shoulder/INPUT_INTERFACE</parent>
      <axis>
        <xyz>0 -1 0</xyz>
        <limit>
          <lower>-1e+16</lower>
          <upper>1e+16</upper>
        </limit>
        <dynamics>
          <damping>0.1</damping>
          <friction>0.1</friction>
          <spring_reference>0</spring_reference>
          <spring_stiffness>0</spring_stiffness>
        </dynamics>
        <use_parent_model_frame>1</use_parent_model_frame>
      </axis>
    </joint>
    <link name='HEBI/Elbow/INPUT_INTERFACE'>
      <pose frame=''>0.325 -0.0885 0.066 3.14159 -0 0</pose>
      <inertial>
        <pose frame=''>-0.0142 -0.0031 0.0165 0 -0 0</pose>
        <mass>0.335</mass>
        <inertia>
          <ixx>0.00015</ixx>
          <ixy>3.41e-05</ixy>
          <ixz>1.18e-05</ixz>
          <iyy>0.000255</iyy>
          <iyz>2.29e-06</iyz>
          <izz>0.00035</izz>
        </inertia>
      </inertial>
      <collision name='HEBI/Elbow/INPUT_INTERFACE_collision'>
        <pose frame=''>0 0 0 0 -0 0</pose>
        <geometry>
          <mesh>
            <scale>0.001 0.001 0.001</scale>
            <uri>model://hebi_description/meshes/X5.stl</uri>
          </mesh>
        </geometry>
      </collision>
      <visual name='HEBI/Elbow/INPUT_INTERFACE_visual'>
        <pose frame=''>0 0 0 0 -0 0</pose>
        <geometry>
          <mesh>
            <scale>0.001 0.001 0.001</scale>
            <uri>model://hebi_description/meshes/X5.stl</uri>
          </mesh>
        </geometry>
      </visual>
    </link>
    <joint name='Shoulder_Elbow/OUTPUT_JOINT' type='fixed'>
      <child>HEBI/Elbow/INPUT_INTERFACE</child>
      <parent>Shoulder_Elbow/INPUT_INTERFACE</parent>
      <axis>
        <dynamics>
          <spring_reference>0</spring_reference>
          <spring_stiffness>0</spring_stiffness>
        </dynamics>
        <use_parent_model_frame>1</use_parent_model_frame>
        <xyz>0 0 1</xyz>
        <limit>
          <lower>-1e+16</lower>
          <upper>1e+16</upper>
        </limit>
      </axis>
      <physics>
        <ode>
          <limit>
            <cfm>0</cfm>
            <erp>0.2</erp>
          </limit>
        </ode>
      </physics>
    </joint>
    <link name='Elbow_Wrist1/INPUT_INTERFACE'>
      <pose frame=''>0.325 -0.0885 0.035 3.14159 -0 0</pose>
      <inertial>
        <pose frame=''>0.1625 0 0.02 0 -0 0</pose>
        <mass>0.402</mass>
        <inertia>
          <ixx>0</ixx>
          <ixy>0</ixy>
          <ixz>0</ixz>
          <iyy>0.00353844</iyy>
          <iyz>0</iyz>
          <izz>0.00353844</izz>
        </inertia>
      </inertial>
      <collision name='Elbow_Wrist1/INPUT_INTERFACE_collision'>
        <pose frame=''>0 0 0 0 -0 0</pose>
        <geometry>
          <mesh>
            <scale>1 1 1</scale>
            <uri>model://hebi_description/meshes/A-2038-02.stl</uri>
          </mesh>
        </geometry>
      </collision>
      <collision name='Elbow_Wrist1/INPUT_INTERFACE_collision_1'>
        <pose frame=''>0.1625 0 0.02 3.14159 1.57079 3.14159</pose>
        <geometry>
          <cylinder>
            <length>0.2996</length>
            <radius>0.016</radius>
          </cylinder>
        </geometry>
      </collision>
      <collision name='Elbow_Wrist1/INPUT_INTERFACE_collision_2'>
        <pose frame=''>0.325 0 0.04 0 -0 0</pose>
        <geometry>
          <mesh>
            <scale>1 1 1</scale>
            <uri>model://hebi_description/meshes/A-2039-02.stl</uri>
          </mesh>
        </geometry>
      </collision>
      <visual name='Elbow_Wrist1/INPUT_INTERFACE_visual'>
        <pose frame=''>0 0 0 0 -0 0</pose>
        <geometry>
          <mesh>
            <scale>1 1 1</scale>
            <uri>model://hebi_description/meshes/A-2038-02.stl</uri>
          </mesh>
        </geometry>
      </visual>
      <visual name='Elbow_Wrist1/INPUT_INTERFACE_visual_1'>
        <pose frame=''>0.1625 0 0.02 3.14159 1.57079 3.14159</pose>
        <geometry>
          <cylinder>
            <length>0.2996</length>
            <radius>0.016</radius>
          </cylinder>
        </geometry>
      </visual>
      <visual name='Elbow_Wrist1/INPUT_INTERFACE_visual_2'>
        <pose frame=''>0.325 0 0.04 0 -0 0</pose>
        <geometry>
          <mesh>
            <scale>1 1 1</scale>
            <uri>model://hebi_description/meshes/A-2039-02.stl</uri>
          </mesh>
        </geometry>
      </visual>
    </link>
    <joint name='HEBI/Elbow/X5_4' type='revolute'>
      <child>Elbow_Wrist1/INPUT_INTERFACE</child>
      <parent>HEBI/Elbow/INPUT_INTERFACE</parent>
      <axis>
        <xyz>0 -0 -1</xyz>
        <limit>
          <lower>-1e+16</lower>
          <upper>1e+16</upper>
        </limit>
        <dynamics>
          <damping>0.1</damping>
          <friction>0.1</friction>
          <spring_reference>0</spring_reference>
          <spring_stiffness>0</spring_stiffness>
        </dynamics>
        <use_parent_model_frame>1</use_parent_model_frame>
      </axis>
    </joint>
    <link name='HEBI/Wrist1/INPUT_INTERFACE'>
      <pose frame=''>0.65 -0.0885 -0.005 3.14159 -0 0</pose>
      <inertial>
        <pose frame=''>-0.0142 -0.0031 0.0165 0 -0 0</pose>
        <mass>0.315</mass>
        <inertia>
          <ixx>0.00015</ixx>
          <ixy>3.41e-05</ixy>
          <ixz>1.18e-05</ixz>
          <iyy>0.000255</iyy>
          <iyz>2.29e-06</iyz>
          <izz>0.00035</izz>
        </inertia>
      </inertial>
      <collision name='HEBI/Wrist1/INPUT_INTERFACE_collision'>
        <pose frame=''>0 0 0 0 -0 0</pose>
        <geometry>
          <mesh>
            <scale>0.001 0.001 0.001</scale>
            <uri>model://hebi_description/meshes/X5.stl</uri>
          </mesh>
        </geometry>
      </collision>
      <visual name='HEBI/Wrist1/INPUT_INTERFACE_visual'>
        <pose frame=''>0 0 0 0 -0 0</pose>
        <geometry>
          <mesh>
            <scale>0.001 0.001 0.001</scale>
            <uri>model://hebi_description/meshes/X5.stl</uri>
          </mesh>
        </geometry>
      </visual>
    </link>
    <joint name='Elbow_Wrist1/OUTPUT_JOINT' type='fixed'>
      <child>HEBI/Wrist1/INPUT_INTERFACE</child>
      <parent>Elbow_Wrist1/INPUT_INTERFACE</parent>
      <axis>
        <dynamics>
          <spring_reference>0</spring_reference>
          <spring_stiffness>0</spring_stiffness>
        </dynamics>
        <use_parent_model_frame>1</use_parent_model_frame>
        <xyz>0 0 1</xyz>
        <limit>
          <lower>-1e+16</lower>
          <upper>1e+16</upper>
        </limit>
      </axis>
      <physics>
        <ode>
          <limit>
            <cfm>0</cfm>
            <erp>0.2</erp>
          </limit>
        </ode>
      </physics>
    </joint>
    <link name='end_effector/INPUT_INTERFACE'>
      <pose frame=''>0.65 -0.0885 -0.036 3.14159 -0 0</pose>
      <inertial>
        <pose frame=''>0 0 0.0005 0 -0 0</pose>
        <mass>0.001</mass>
        <inertia>
          <ixx>0.001</ixx>
          <ixy>0</ixy>
          <ixz>0</ixz>
          <iyy>0.001</iyy>
          <iyz>0</iyz>
          <izz>0.001</izz>
        </inertia>
      </inertial>
      <collision name='end_effector/INPUT_INTERFACE_collision'>
        <pose frame=''>0 0 0.0005 0 -0 0</pose>
        <geometry>
          <box>
            <size>0.001 0.001 0.001</size>
          </box>
        </geometry>
      </collision>
      <visual name='end_effector/INPUT_INTERFACE_visual'>
        <pose frame=''>0 0 0.0005 0 -0 0</pose>
        <geometry>
          <box>
            <size>0.001 0.001 0.001</size>
          </box>
        </geometry>
      </visual>
    </link>
    <joint name='HEBI/Wrist1/X5_1' type='revolute'>
      <child>end_effector/INPUT_INTERFACE</child>
      <parent>HEBI/Wrist1/INPUT_INTERFACE</parent>
      <axis>
        <xyz>0 -0 -1</xyz>
        <limit>
          <lower>-1e+16</lower>
          <upper>1e+16</upper>
        </limit>
        <dynamics>
          <damping>0.1</damping>
          <friction>0.1</friction>
          <spring_reference>0</spring_reference>
          <spring_stiffness>0</spring_stiffness>
        </dynamics>
        <use_parent_model_frame>1</use_parent_model_frame>
      </axis>
    </joint>
    <static>0</static>
    <plugin name='hebi_gazebo_plugin' filename='libhebi_gazebo_plugin.so'/>
  </model>
</sdf>
