<?xml version="1.0"?>
<robot xmlns:xacro="http://www.ros.org/wiki/xacro">

  <xacro:macro name="parallel_gripper_outer_subassembly" params="name prefix">
    <link name="${name}/${prefix}_finger">
      <visual>
        <origin xyz="-0.006 -0.0055 -0.0045" rpy="${pi/2} 0 ${pi/2}" />
        <geometry>
          <mesh filename="package://hebi_description/meshes/PM-2221-01.stl" scale="0.001 0.001 0.001"/>
        </geometry>
        <xacro:silver_material/>
      </visual>
    </link>
    <gazebo reference="${name}/${prefix}_finger">
      <xacro:gazebo_silver_material/>
    </gazebo>

    <link name="${name}/${prefix}_outer_linkage">
      <visual>
        <origin xyz="-0.0115 0.029 -0.004" rpy="${pi/2} 0 0" />
        <geometry>
          <mesh filename="package://hebi_description/meshes/PM-2358-02.stl" scale="0.001 0.001 0.001"/>
        </geometry>
        <xacro:black_material/>
      </visual>
    </link>
    <gazebo reference="${name}/${prefix}_outer_linkage">
      <xacro:gazebo_black_material/>
    </gazebo>

    <link name="${name}/${prefix}_gripper">
      <visual>
        <origin xyz="-0.006 -0.004 0.0115" rpy="0 ${pi/2} 0" />
        <geometry>
          <mesh filename="package://hebi_description/meshes/PM-2360-02.stl" scale="0.001 0.001 0.001"/>
        </geometry>
        <xacro:black_material/>
      </visual>
      <collision>
        <origin xyz="-0.006 -0.004 0.0115" rpy="0 ${pi/2} 0" />
        <geometry>
          <mesh filename="package://hebi_description/meshes/PM-2360-02.stl" scale="0.001 0.001 0.001"/>
        </geometry>
      </collision>
    </link>
    <gazebo reference="${name}/${prefix}_gripper">
      <xacro:gazebo_black_material/>
    </gazebo>

    <joint name="${name}/input_${prefix}_finger" type="revolute">
      <xacro:if value="${prefix == 'l'}">
        <origin xyz="0 0.0125 .0115" rpy="0 0 0" />
      </xacro:if>
      <xacro:if value="${prefix == 'r'}">
        <origin xyz="0 -0.0125 .0115" rpy="0 0 ${pi}" />
        <mimic joint="${name}/input_l_finger" multiplier="1.0" offset="0" />
      </xacro:if>
      <parent link="${name}/INPUT_INTERFACE"/>
      <child link="${name}/${prefix}_finger"/>
      <limit effort="1000" velocity="1000" lower="0" upper="1.1675"/>
    </joint>
    <joint name="${name}/${prefix}_finger_${prefix}_outer_linkage" type="fixed">
      <origin xyz="0 0.015 0" rpy="0 0 0" />
      <parent link="${name}/${prefix}_finger"/>
      <child link="${name}/${prefix}_outer_linkage"/>
    </joint>
    <gazebo reference="${name}/${prefix}_finger_${prefix}_outer_linkage">
      <disableFixedJointLumping>true</disableFixedJointLumping>
      <preserveFixedJoint>true</preserveFixedJoint>
    </gazebo>
    <joint name="${name}/${prefix}_outer_linkage_${prefix}_gripper" type="continuous">
      <origin xyz="0 0.025 0.018" rpy="0 0 0" />
      <parent link="${name}/${prefix}_outer_linkage"/>
      <child link="${name}/${prefix}_gripper"/>
      <mimic joint="${name}/input_l_finger" multiplier="-1.0" offset="${pi/2}" />
    </joint>
  </xacro:macro>

  <xacro:macro name="parallel_gripper_inner_subassembly" params="name prefix">
    <link name="${name}/${prefix}_inner_linkage">
      <visual>
        <origin xyz="-0.0115 -0.004 -0.004" rpy="0 0 0" />
        <geometry>
          <mesh filename="package://hebi_description/meshes/PM-2359-02.stl" scale="0.001 0.001 0.001"/>
        </geometry>
        <xacro:black_material/>
      </visual>
    </link>
    <gazebo reference="${name}/${prefix}_inner_linkage">
      <xacro:gazebo_black_material/>
    </gazebo>

    <joint name="${name}/center_hub_${prefix}_inner_linkage" type="continuous">
      <xacro:if value="${prefix == 'l'}">
        <origin xyz="0 0.005 0.023" rpy="0 0 0" />
      </xacro:if>
      <xacro:if value="${prefix == 'r'}">
        <origin xyz="0 -0.005 0.023" rpy="0 0 ${pi}" />
      </xacro:if>
      <parent link="${name}/center_hub"/>
      <child link="${name}/${prefix}_inner_linkage"/>
      <mimic joint="${name}/input_l_finger" multiplier="1.0" offset="-1.145" />
    </joint>
  </xacro:macro>

  <xacro:macro name="gripper" params="name type:=Custom mass:=0.001 com_trans:='0 0 0.0005' output_trans:='0 0 0'">
    <xacro:property name="com_trans_list" value="${com_trans.split(' ')}"/>
    <xacro:property name="len" value="${sqrt( pow(float(com_trans_list[0]), 2) + pow(float(com_trans_list[1]), 2) + pow(float(com_trans_list[2]), 2) )}"/>
    <xacro:if value="${type == 'Custom'}">
      <link name="${name}/INPUT_INTERFACE">
        <collision>
          <origin xyz="0 0 0.0005" rpy="0 0 0"/>
          <geometry>
            <box size="0.001 0.001 0.001" rpy="0 0 0"/>
          </geometry>
        </collision>
        <visual>
          <origin xyz="0 0 0.0005" rpy="0 0 0"/>
          <geometry>
            <box size="0.001 0.001 0.001" rpy="0 0 0"/>
          </geometry>
        </visual>
        <inertial>
          <origin xyz="${com_trans}" rpy="0 0 0"/>
          <mass value="${mass}"/>
          <inertia
            ixx="${mass*len*len*2.0/5.0}" ixy="0.0" ixz="0.0"
            iyy="${mass*len*len*2.0/5.0}" iyz="0.0"
            izz="${mass*len*len*2.0/5.0}"/>
        </inertial>
      </link>
    </xacro:if>

    <xacro:if value="${type.endswith('Parallel')}">
      <!-- The base body of the gripper -->
      <link name="${name}/INPUT_INTERFACE">
        <visual>
          <origin xyz="0 0 0.00375" />
            <geometry>
            <cylinder length="0.0075" radius=".0225" />
          </geometry>
          <xacro:black_material/>
        </visual>
      </link>
      <gazebo reference="${name}/INPUT_INTERFACE">
        <xacro:gazebo_black_material/>
      </gazebo>

      <!-- Tree branch for center hub -->
      <link name="${name}/center_hub">
        <visual>
          <origin xyz="-0.0225 0.0225 0" rpy="${pi/2} 0 0" />
          <geometry>
            <mesh filename="package://hebi_description/meshes/PM-2357-02.stl" scale="0.001 0.001 0.001"/>
          </geometry>
          <xacro:black_material/>
        </visual>
      </link>
      <gazebo reference="${name}/center_hub">
        <xacro:gazebo_black_material/>
      </gazebo>
      
      <joint name="${name}/input_center_hub" type="fixed">
        <origin xyz="0 0 0.0045" rpy="0 0 0" />
        <parent link="${name}/INPUT_INTERFACE"/>
        <child link="${name}/center_hub"/>
      </joint>
      <gazebo reference="${name}/input_center_hub">
        <disableFixedJointLumping>true</disableFixedJointLumping>
        <preserveFixedJoint>true</preserveFixedJoint>
      </gazebo>

      <!-- Tree branches for fingers, outer linkages, and grippers -->
      <xacro:parallel_gripper_outer_subassembly name="${name}" prefix="l"/>
      <xacro:parallel_gripper_outer_subassembly name="${name}" prefix="r"/>

      <!-- Tree branches for inner linkages -->
      <xacro:parallel_gripper_inner_subassembly name="${name}" prefix="l"/>
      <xacro:parallel_gripper_inner_subassembly name="${name}" prefix="r"/>
    </xacro:if>

  </xacro:macro>
</robot>

